<?xml version='1.0'?>
<sdf version='1.7'>
    <model name='buggy_simulated_description'>
        <!-- BEGIN LINKS RELATED TO BUGGY-->
        <link name='base_footprint'/>
        
        <link name='base_link'>
            <pose>0 0 0 0 0 0</pose>
            <inertial>
                <inertial>
                    <mass>54.0</mass>
                    <pose>0 0 0 0 0 0</pose>
                    <inertia>
                        <ixx>1.35045</ixx>
                        <ixy>0.0</ixy>
                        <iyy>3.8039625</iyy>
                        <ixz>0.0</ixz>
                        <iyz>0.0</iyz>
                        <izz>2.8135125</izz>
                    </inertia>
                </inertial>
            </inertial>
            <visual name='visual'>
                <pose>0 0 0 0 0 0</pose>
                <geometry>
                    <box>
                    <size>0.765 0.510 0.20</size>
                  </box>
                </geometry>
                 <material>
            <script>
              <uri>file://media/materials/scripts/gazebo.material</uri>
              <name>Gazebo/Gray</name>
            </script>
          </material>
            </visual>
            <collision name='collision'>
                <pose>0 0 0 0 0 0</pose>
                <geometry>
                      <box>
                    <size>0.765 0.510 0.20</size>
                  </box>
                </geometry>
            </collision>
        </link>
        
         <link name='base_camera_left'>
             <pose>0.3975 0.06 0.225 0 0 0</pose>
            <inertial>
                <inertial>
                    <mass>0.5</mass>
                    <pose>0.3975 0.06 0.225 0 0 0</pose>
                    <inertia>
                        <ixx>0.0054375</ixx>
                        <ixy>0.0</ixy>
                        <iyy>0.000075</iyy>
                        <ixz>0.0</ixz>
                        <iyz>0.0</iyz>
                        <izz>0.0054375</izz>
                    </inertia>
                </inertial>
            </inertial>
            <visual name='visual'>
                <pose>0 0 0 0 0 0</pose>
                <geometry>
                    <box>
                    <size>0.03 0.03 0.25</size>
                  </box>
                </geometry>
                <material>
            <script>
              <uri>file://media/materials/scripts/gazebo.material</uri>
              <name>Gazebo/Gray</name>
            </script>
          </material>
            </visual>
            <collision name='collision'>
                <pose>0 0 0 0 0 0</pose>
                <geometry>
                      <box>
                    <size>0.03 0.03 0.25</size>
                  </box>
                </geometry>
            </collision>
        </link>
        
         <link name='base_camera_right'>
            <pose>0.3975 -0.06 0.225 0 0 0</pose>
            <inertial>
                <inertial>
                    <mass>0.5</mass>
                    <pose>0.3975 -0.06 0.225 0 0 0</pose>
                    <inertia>
                        <ixx>0.0054375</ixx>
                        <ixy>0.0</ixy>
                        <iyy>0.000075</iyy>
                        <ixz>0.0</ixz>
                        <iyz>0.0</iyz>
                        <izz>0.0054375</izz>
                    </inertia>
                </inertial>
            </inertial>
            <visual name='visual'>
                <pose>0 0 0 0 0 0</pose>
                <geometry>
                    <box>
                    <size>0.03 0.03 0.25</size>
                  </box>
                </geometry>
                 <material>
            <script>
              <uri>file://media/materials/scripts/gazebo.material</uri>
              <name>Gazebo/Gray</name>
            </script>
          </material>
            </visual>
            <collision name='collision'>
                <pose>0 0 0 0 0 0</pose>
                <geometry>
                      <box>
                    <size>0.03 0.03 0.25</size>
                  </box>
                </geometry>
            </collision>
        </link>
        
         <link name='base_camera_center'>
            <pose>0.3975 0 0.365 0 0 0</pose>
            <inertial>
                <inertial>
                    <mass>0.5</mass>
                    <pose>0.3975 0 0.365 0 0 0</pose>
                    <inertia>
                        <ixx>0.0054375</ixx>
                        <ixy>0.0</ixy>
                        <iyy>0.000075</iyy>
                        <ixz>0.0</ixz>
                        <iyz>0.0</iyz>
                        <izz>0.0054375</izz>
                    </inertia>
                </inertial>
            </inertial>
            <visual name='visual'>
                <pose>0 0 0 0 0 0</pose>
                <geometry>
                    <box>
                    <size>0.03 0.15 0.03</size>
                  </box>
                </geometry>
                 <material>
            <script>
              <uri>file://media/materials/scripts/gazebo.material</uri>
              <name>Gazebo/Gray</name>
            </script>
          </material>
            </visual>
            <collision name='collision'>
                <pose>0 0 0 0 0 0</pose>
                <geometry>
                      <box>
                    <size>0.03 0.15 0.03</size>
                  </box>
                </geometry>
            </collision>
        </link>

         <link name='base_velodyne'>
            <pose>0.51 0 0.335 0 0 0</pose>
            <inertial>
                <inertial>
                    <mass>1.0</mass>
                    <pose>0.51 0 335 0 0 0</pose>
                    <inertia>
                        <ixx>0.00170</ixx>
                        <ixy>0.0</ixy>
                        <iyy>0.00433</iyy>
                        <ixz>0.0</ixz>
                        <iyz>0.0</iyz>
                        <izz>0.002775</izz>
                    </inertia>
                </inertial>
            </inertial>
            <visual name='visual'>
                <pose>0 0 0 0 0 0</pose>
                <geometry>
                    <box>
                    <size>0.20 0.15 0.03</size>
                  </box>
                </geometry>
                 <material>
            <script>
              <uri>file://media/materials/scripts/gazebo.material</uri>
              <name>Gazebo/Gray</name>
            </script>
          </material>
            </visual>
            <collision name='collision'>
                <pose>0 0 0 0 0 0</pose>
                <geometry>
                      <box>
                    <size>>0.20 0.15 0.03</size>
                  </box>
                </geometry>
            </collision>
        </link>

        
        <link name='imu_link'>
        <sensor name='imu' type='imu'>
          <always_on>1</always_on>
          <update_rate>200</update_rate>
          <imu>
            <angular_velocity>
              <x>
                <noise type='gaussian'>
                  <mean>0</mean>
                  <stddev>0.0002</stddev>
                </noise>
              </x>
              <y>
                <noise type='gaussian'>
                  <mean>0</mean>
                  <stddev>0.0002</stddev>
                </noise>
              </y>
              <z>
                <noise type='gaussian'>
                  <mean>0</mean>
                  <stddev>0.0002</stddev>
                </noise>
              </z>
            </angular_velocity>
            <linear_acceleration>
              <x>
                <noise type='gaussian'>
                  <mean>0</mean>
                  <stddev>0.017</stddev>
                </noise>
              </x>
              <y>
                <noise type='gaussian'>
                  <mean>0</mean>
                  <stddev>0.017</stddev>
                </noise>
              </y>
              <z>
                <noise type='gaussian'>
                  <mean>0</mean>
                  <stddev>0.017</stddev>
                </noise>
              </z>
            </linear_acceleration>
            <angular_velocity/>
            <linear_acceleration/>
          </imu>
          <plugin name='imu' filename='libgazebo_ros_imu_sensor.so'>
            <ros>
              <remapping>~/out:=imu</remapping>
            </ros>
          </plugin>
        </sensor>
        <self_collide>0</self_collide>
        <inertial>
          <pose>0 0 0 0 -0 0</pose>
          <inertia>
            <ixx>1</ixx>
            <ixy>0</ixy>
            <ixz>0</ixz>
            <iyy>1</iyy>
            <iyz>0</iyz>
            <izz>1</izz>
          </inertia>
          <mass>1</mass>
        </inertial>
        <enable_wind>0</enable_wind>
        <kinematic>0</kinematic>
      </link>


        <link name='laser'>
            <pose>0.61 0 0.23 0 0 0</pose>
             <inertial>
                <inertial>
                    <mass>1.0</mass>
                    <pose>0.61 0 0.23 0 0 0</pose>
                    <inertia>
                        <ixx>0.13354740</ixx>
                        <ixy>0.0</ixy>
                        <iyy>0.010846112</iyy>
                        <ixz>0.0</ixz>
                        <iyz>0.0</iyz>
                        <izz>0.15008628</izz>
                    </inertia>
                </inertial>
            </inertial>
            <visual name='visual'>
                <pose>-0.05 0 -0.03 0 0 0</pose>
                <geometry>
                  <mesh>
                <uri>model://buggy_mobile_description/meshes/LMS1xx_small.dae</uri>
                  </mesh>
                </geometry>
            </visual>
            <collision name='collision'>
                <pose>-0.05 0 -0.03 0 0 0</pose>
                <geometry>
                  <mesh>
                      <uri>model://buggy_mobile_description/meshes/LMS1xx_collision.stl</uri>
                  </mesh>
                </geometry>
            </collision>
       
        
        <!-- insert lidar sensor plugins here -->
      <sensor name="hls_lfcd_lds" type="ray">
        <always_on>true</always_on>
        <visualize>true</visualize>
        <pose>0 0 0 0 0 0</pose>
        <update_rate>10</update_rate>
        <ray>
          <scan>
            <horizontal>
              <samples>360</samples>
              <resolution>1.000000</resolution>
              <min_angle>-2.350000</min_angle>
              <max_angle>2.350000</max_angle>
            </horizontal>
          </scan>
          <range>
            <min>0.120000</min>
            <max>20.00</max>
            <resolution>0.015000</resolution>
          </range>
          <noise>
            <type>gaussian</type>
            <mean>0.0</mean>
            <stddev>0.01</stddev>
          </noise>
        </ray>
        <!--plugin name="laserscan" filename="libgazebo_ros_ray_sensor.so">
          <ros>
            <remapping>~/out:=scan</remapping>
          </ros>
          <output_type>sensor_msgs/LaserScan</output_type>
          <frame_name>laser</frame_name>
        </plugin-->
      </sensor>
      </link>

     <link name="velodyne_link">
            <pose>0.3975 0 0.38 0 0 0</pose>
             <inertial>
                <inertial>
                    <mass>1.0</mass>
                    <pose>0.3975 0 0.38 0 0 0</pose>
                    <inertia>
                        <ixx>0.0013354740</ixx>
                        <ixy>0.0</ixy>
                        <iyy>0.0010846112</iyy>
                        <ixz>0.0</ixz>
                        <iyz>0.0</iyz>
                        <izz>0.0015008628</izz>
                    </inertia>
                </inertial>
            </inertial>
            <collision name="collision">
                <pose>0 0 0 1.5707 0 3.1416</pose>
                <geometry>
                    
                    <mesh>
                        <uri>model://buggy_mobile_description/meshes/velodyne-vlp16.stl</uri>
                        <scale>0.02 0.02 0.02</scale>
                    </mesh>
                
                </geometry>
            </collision>
            <visual name="visual">
                <pose>0 0 0 1.5707 0 3.1416</pose>
                <geometry>
                     <mesh>
                        <uri>model://buggy_mobile_description/meshes/velodyne-vlp16.stl</uri>
                        <scale>0.02 0.02 0.02</scale>
                    </mesh>
                </geometry>
                 <material>
            <script>
              <uri>file://media/materials/scripts/gazebo.material</uri>
              <name>Gazebo/Black</name>
            </script>
          </material>
            </visual>
            <sensor type="gpu_ray" name="VLP16">
                <visualize>false</visualize>
                <update_rate>10</update_rate>
                <ray>
                    <scan>
                        <horizontal>
                            <samples>1875</samples>
                            <resolution>1</resolution>
                            <min_angle>-3.14</min_angle>
                            <max_angle>3.14</max_angle>
                        </horizontal>
                        <vertical>
                            <samples>16</samples>
                            <resolution>1</resolution>
                            <min_angle>-0.261799</min_angle>
                            <max_angle>0.261799</max_angle>
                        </vertical>
                    </scan>
                    <range>
                        <min>1.0</min>
                        <max>20.0</max>
                        <resolution>0.01</resolution>
                    </range>
                    <noise>
                        <type>gaussian</type>
                        <mean>0.0</mean>
                        <stddev>0.0</stddev>
                    </noise>
                </ray>
                <!--plugin name="gazebo_ros_laser_controller" filename="libgazebo_ros_velodyne_laser.so">
                    <topicName>/velodyne_points</topicName>
                    <frameName>velodyne_link</frameName>
                    <min_range>1.0</min_range>
                    <max_range>20.0</max_range>
                    <gaussianNoise>0.008</gaussianNoise>
                </plugin-->
            </sensor>
        </link>
        
      <link name="zed2_camera_center">
       <pose>0.60 0 0.365 0 0 0</pose>     
      <inertial>
                <inertial>
                    <mass>1.0</mass>
                    <pose>0.60 0 0.365 0 0 0</pose>
                    <inertia>
                        <ixx>0.0013354740</ixx>
                        <ixy>0.0</ixy>
                        <iyy>0.0010846112</iyy>
                        <ixz>0.0</ixz>
                        <iyz>0.0</iyz>
                        <izz>0.0015008628</izz>
                    </inertia>
                </inertial>
            </inertial>
      <visual name="visual">
         <pose>0 0 0 0 0 0</pose>    
        <geometry>
          <mesh>
            <uri>model://buggy_mobile_description/meshes/zed2.stl</uri>
          </mesh>
        </geometry>
        <material>
          <script>
            <uri>file://media/materials/scripts/gazebo.material</uri>
            <name>Gazebo/Grey</name>
          </script>
        </material>
      </visual>
       <collision name="collision">
                 <pose>0 0 0 0 0 0</pose>   
                <geometry>
                  <mesh>
            <uri>model://buggy_mobile_description/meshes/zed2.stl</uri>
          </mesh>  
                </geometry>
            </collision>
    </link>
    
    <link name="zed2_right_camera_optical_frame">
      <!-- insert camera sensor plugins here -->

      <sensor name="camera" type="camera">
        <always_on>true</always_on>
        <visualize>true</visualize>
        <update_rate>30</update_rate>
        <pose>0.60 -0.06 0.365 0 0 0</pose>
        <camera name="intel_realsense_r200">
          <horizontal_fov>1.02974</horizontal_fov>
          <image>
            <width>1920</width>
            <height>1080</height>
            <format>R8G8B8</format>
          </image>
          <clip>
            <near>0.02</near>
            <far>300</far>
          </clip>
          <noise>
            <type>gaussian</type>
            
            <mean>0.0</mean>
            <stddev>0.007</stddev>
          </noise>
        </camera>
          <!--plugin name="camera_driver" filename="libgazebo_ros_camera.so">
            <ros>
              <namespace>camera</namespace>
           <qos>
            <topic name="/camera/camera/image_raw">
                <publisher>
                    <reliability>reliable</reliability>
                </publisher>
            </topic>
            <topic name="/camera/camera/camera_info">
                <publisher>
                    <reliability>reliable</reliability>
                </publisher>
            </topic>
           </qos>
      
            </ros>
            
          </plugin-->
      </sensor>

    </link>  
        <link name='steering_wheel'>
            <pose>0.400132 9.3e-05 0.399996 -5.9e-05 -1.57 6.4e-05</pose>
            <inertial>
                <mass>0.2</mass>
                <inertia>
                    <ixx>0.00014583300</ixx>
                    <ixy>0</ixy>
                    <ixz>0</ixz>
                    <iyy>0.00014583300</iyy>
                    <iyz>0</iyz>
                    <izz>0.00012500000</izz>
                </inertia>
            </inertial>
            <!--visual name='visual'>
                <pose>0 0 0 1.57 -0 0</pose>
                <geometry>
                    <mesh>
                        <uri>model://botanbot/meshes/wheel.stl</uri>
                        <scale>0.5 0.5 1</scale>
                    </mesh>
                </geometry>
                <material>
                    <ambient>0.19225 0.19225 0.19225 1.0</ambient>
                    <diffuse>0.50754 0.50754 0.50754 1.0</diffuse>
                    <specular>0.508273 0.508273 0.508273 1.0</specular>
                    <emissive>0.0 0.0 0.0 0.0</emissive>
                </material>
            </visual>
            <collision name="collision">
                <geometry>
                    <sphere>
                        <radius>0.15</radius>
                    </sphere>
                </geometry>
                <surface>
                    <friction>
                        <ode>
                            <mu>0.9</mu>
                            <mu2>0.9</mu2>
                            <slip1>0.0</slip1>
                            <slip2>0.0</slip2>
                            <kp>10000000.0</kp>
                            <kd>1.0</kd>
                        </ode>
                    </friction>
                    <contact>
                        <ode>
                            <min_depth>0.001</min_depth>
                            <kp>1e9</kp>
                        </ode>
                    </contact>
                </surface>
            </collision-->
        </link>

        <link name='front_left_wheel'>
            <inertial>
                <mass>11</mass>
                <inertia>
                    <ixx>0.549</ixx>
                    <ixy>0.0</ixy>
                    <iyy>0.549</iyy>
                    <ixz>0.0</ixz>
                    <iyz>0.0</iyz>
                    <izz>0.549</izz>
                </inertia>
            </inertial>
            <pose>0.3825 0.345 0.01 0 -0 1.57079</pose>
            <visual name='visual'>
                <pose>0 0 0 0 -0 3.141592</pose>
                <geometry>
                    <mesh>
                        <uri>model://buggy_mobile_description/meshes/wheel_a.stl</uri>
                        <scale>0.0032 0.0032 0.0032</scale>
                    </mesh>
                </geometry>
                 <material>
            <script>
              <uri>file://media/materials/scripts/gazebo.material</uri>
              <name>Gazebo/Orange</name>
            </script>
          </material>
            </visual>
            <collision name='collision'>
                <pose>0.05 0 0 0 -0 1.57079</pose>
                <geometry>
                    <sphere>
                        <radius>0.14</radius>
                    </sphere>
                </geometry>
                <surface>
                    <friction>
                        <ode>
                            <mu>0.8</mu>
                            <mu2>0.8</mu2>
                        </ode>
                    </friction> 
                </surface>
            </collision>
        </link>

        <link name='front_right_wheel'>
            <inertial>
                <mass>11</mass>
                <inertia>
                    <ixx>0.549</ixx>
                    <ixy>0.0</ixy>
                    <iyy>0.549</iyy>
                    <ixz>0.0</ixz>
                    <iyz>0.0</iyz>
                    <izz>0.549</izz>
                </inertia>
            </inertial>
            <pose>0.3825 -0.345 0.01 0 0 1.57079</pose>
            <visual name='visual'>
                <pose>0 0 0 0 -0 0</pose>
                <geometry>
                    <mesh>
                        <uri>model://buggy_mobile_description/meshes/wheel_a.stl</uri>
                        <scale>0.0032 0.0032 0.0032</scale>
                    </mesh>
                </geometry>
                 <material>
            <script>
              <uri>file://media/materials/scripts/gazebo.material</uri>
              <name>Gazebo/Orange</name>
            </script>
          </material>
            </visual>
            <collision name='collision'>
                <pose>-0.05 0 0 0 -0 1.57079</pose>
                <geometry>
                    <sphere>
                        <radius>0.14</radius>
                    </sphere>
                </geometry>
                <surface>
                    <friction>
                        <ode>
                            <mu>0.8</mu>
                            <mu2>0.8</mu2>
                        </ode>
                    </friction>
                </surface>
            </collision>
        </link>

        <link name='rear_left_wheel'>
            <inertial>
                <mass>11</mass>
                <inertia>
                    <ixx>0.549</ixx>
                    <ixy>0.0</ixy>
                    <iyy>0.549</iyy>
                    <ixz>0.0</ixz>
                    <iyz>0.0</iyz>
                    <izz>0.549</izz>
                </inertia>
            </inertial>
            <pose>-0.30 0.29 0.01 0 -0 1.57079</pose>
            <visual name='visual'>
                <pose>0.02 0 0 0 -0 -3.141592</pose>
                <geometry>
                    <mesh>
                        <uri>model://buggy_mobile_description/meshes/wheel_a.stl</uri>
                        <scale>0.0032 0.0032 0.0032</scale>
                    </mesh>
                </geometry>
                 <material>
            <script>
              <uri>file://media/materials/scripts/gazebo.material</uri>
              <name>Gazebo/Orange</name>
            </script>
          </material>
            </visual>
            <collision name='collision'>
                <laser_retro>0</laser_retro>
                <max_contacts>10</max_contacts>
                <pose>0.05 0 0 0 -0 1.57079</pose>
                <geometry>
                    <sphere>
                        <radius>0.14</radius>
                    </sphere>
                </geometry>
                <surface>
                    <friction>
                        <ode>
                            <mu>0.8</mu>
                            <mu2>0.8</mu2>  
                        </ode>
                    </friction>
                </surface>
            </collision>
        </link>

        <link name='rear_right_wheel'>
            <inertial>
                <mass>11</mass>
                <inertia>
                    <ixx>0.549</ixx>
                    <ixy>0.0</ixy>
                    <iyy>0.549</iyy>
                    <ixz>0.0</ixz>
                    <iyz>0.0</iyz>
                    <izz>0.549</izz>
                </inertia>
            </inertial>
            <pose>-0.30 -0.29 0.01 0 -0 1.57079</pose>
            <visual name='visual'>
                <pose>-0.02 0 0 0 -0 0</pose>
                <geometry>
                    <mesh>
                        <uri>model://buggy_mobile_description/meshes/wheel_a.stl</uri>
                        <scale>0.0032 0.0032 0.0032</scale>
                    </mesh>
                </geometry>
                 <material>
            <script>
              <uri>file://media/materials/scripts/gazebo.material</uri>
              <name>Gazebo/Orange</name>
            </script>
          </material>
            </visual>
            <collision name='collision'>
                <laser_retro>0</laser_retro>
                <max_contacts>10</max_contacts>
                <pose>-0.05 0 0 0 -0 1.57079</pose>
                <geometry>
                    <sphere>
                        <radius>0.14</radius>
                    </sphere>
                </geometry>
                <surface>
                    <friction>
                        <ode>
                            <mu>0.8</mu>
                            <mu2>0.8</mu2>
                        </ode>
                    </friction> 
                </surface>
            </collision>
        </link>

        <link name='rear_axle'>
            <inertial>
                <mass>30.0</mass>
                <inertia>
                    <ixx>0.08437499999999999</ixx>
                    <ixy>0.0</ixy>
                    <iyy>4.64581</iyy>
                    <ixz>0.0</ixz>
                    <iyz>0.0</iyz>
                    <izz>4.64581</izz>
                </inertia>
            </inertial>
            <pose>-0.30 0 0 0 0 1.5707</pose>
            <visual name='visual'>
                <pose>0 0 0 1.579 -0 1.57079</pose>
                <geometry>
                    <cylinder>
                        <radius>0.04</radius>
                        <length>0.55</length>
                    </cylinder>
                </geometry>
                 <material>
            <script>
              <uri>file://media/materials/scripts/gazebo.material</uri>
              <name>Gazebo/Gray</name>
            </script>
          </material>
            </visual>
            <collision name='collision'>
                <laser_retro>0</laser_retro>
                <max_contacts>10</max_contacts>
                <pose>0 0 0 1.57079 -0 1.57079</pose>
                <geometry>
                    <cylinder>
                        <radius>0.04</radius>
                        <length>0.550</length>
                    </cylinder>
                </geometry>
            </collision>
        </link>
        <!-- END LINKS RELATED TO BUGGY    -->
        <!--////////////////////////////////    -->
        <!-- BEGIN JOINTS RELATED TO BUGGY -->
        <joint name="base_footprint_joint" type="fixed">
            <parent>base_footprint</parent>
            <child>base_link</child>
            <pose>0.0 0.0 0.1 0 0 0</pose>
        </joint>

        <joint name='base_to_camera_base_left' type='fixed'>
            <parent>base_link</parent>
            <child>base_camera_left</child>
            <pose>0 0 0 0 0 0</pose>
        </joint>
        
          <joint name='base_to_camera_base_right' type='fixed'>
            <parent>base_link</parent>
            <child>base_camera_right</child>
            <pose>0 0 0 0 0 0</pose>
          </joint>

        <joint name='base_to_camera_base_center' type='fixed'>
            <parent>base_link</parent>
            <child>base_camera_center</child>
            <pose>0 0 0 0 0 0</pose>
          </joint>  
          
         <joint name='chassis_to_base_sick' type='fixed'>
            <parent>base_link</parent>
            <child>base_velodyne</child>
            <pose>0 0 0 0 0 0</pose>
          </joint> 
          
          <joint name='sick_joint' type='fixed'>
            <parent>base_link</parent>
            <child>laser</child>
            <pose>0 0 0 0 0 0</pose>
          </joint> 
          
           <joint name="base_to_velodyne_link" type="fixed">
            <parent>base_link</parent>
            <child>velodyne_link</child>
            <pose>0 0 0 0 0 0</pose>
        </joint>  
        
         <joint name="zed2_right_camera_optical_joint" type="fixed">
            <parent>zed2_camera_center</parent>
            <child>zed2_right_camera_optical_frame</child>
            <pose>0 0 0 -1.57079 0 -1.57079</pose>
        </joint> 
         
        <joint name="zed2_camera_center_joint" type="fixed">
            <parent>base_link</parent>
            <child>zed2_camera_center</child>
            <pose>0 0 0 0 0 0</pose>
        </joint>  
          <joint name='imu_joint' type='fixed'>
        <parent>base_link</parent>
        <child>imu_link</child>
        <pose>0 0 0 0 -0 0</pose>
          <axis>
          <xyz>0 0 1</xyz>
          <limit>
            <lower>-1e+16</lower>
            <upper>1e+16</upper>
          </limit>
           </axis>
         </joint>
      
        <joint name='rear_axle_joint' type='revolute'>
            <parent>base_link</parent>
            <child>rear_axle</child>
            <pose>0 0 0 0 0 0</pose>
            <axis>
                <xyz>0 1 0</xyz>
                <limit>
                    <lower>-0.05089058524173028</lower>
                    <upper>0.05089058524173028</upper>
                </limit>
                <dynamics>
                    <spring_stiffness>20000.0</spring_stiffness>
                    <damping>2000.0</damping>
                </dynamics>
            </axis>
        </joint>
        
        <joint name='front_left_combined_joint' type='universal'>
            <parent>base_link</parent>
            <child>front_left_wheel</child>
            <pose>0 0 0 0 0 0</pose>
            <axis>
                <xyz>0 0 1</xyz>
                <limit>
                    <lower>-0.8727</lower>
                    <upper>0.8727</upper>
                </limit>
                <dynamics>
                    <friction>4.0</friction>
                </dynamics>
            </axis>
            <axis2>
                <xyz>1 0 0</xyz>
                <dynamics>
                    <friction>2.0</friction>
                </dynamics>
            </axis2>
        </joint>
        
        <joint name='front_right_combined_joint' type='universal'>
            <parent>base_link</parent>
            <child>front_right_wheel</child>
            <pose>0 0 0 0 0 0</pose>
            <axis>
                <xyz>0 0 1</xyz>
                <limit>
                    <lower>-0.8727</lower>
                    <upper>0.8727</upper>
                </limit>
                <dynamics>
                    <friction>4.0</friction>
                </dynamics>
            </axis>
            <axis2>
                <xyz>1 0 0</xyz>
                <dynamics>
                    <friction>2.0</friction>
                </dynamics>
            </axis2>
        </joint>

        <joint name='rear_left_joint' type='revolute'>
            <parent>rear_axle</parent>
            <child>rear_left_wheel</child>
            <pose>0 0 0 0 0 0</pose>
            <axis>
                <xyz>1 0 0</xyz>
                <dynamics>
                    <friction>2.0</friction>
                </dynamics>
            </axis>
        </joint>

        <joint name='rear_right_joint' type='revolute'>
            <parent>rear_axle</parent>
            <child>rear_right_wheel</child>
            <pose>0 0 0 0 -0 0</pose>
            <axis>
                <xyz>1 0 0</xyz>
                <dynamics>
                    <friction>2.0</friction>
                </dynamics>
            </axis>
        </joint>

        <joint name="steering_joint" type="revolute">
            <pose>-0.002 0 0 0 0 0</pose>
            <parent>base_link</parent>
            <child>steering_wheel</child>
            <axis>
                <xyz>0.0 0.0 1.0</xyz>
                <limit>
                    <lower>-35.0</lower>
                    <upper>35.0</upper>
                </limit>
                <use_parent_model_frame>true
                </use_parent_model_frame>
            </axis>
        </joint>

        <!-- END JOINTS RELATED TO BUGGY   -->
        <!-- ////////////////////////////////   -->

        <!-- ////////////////////////////////    -->
        <!-- BEGIN BUGGY PLUGINS              -->
        <plugin name='botanbot_ackermann_drive' filename='libbotanbot_ackermann_drive.so'>
            <ros>
                <namespace />
                <remapping>cmd_vel:=/buggy/cmd_vel</remapping>
                <remapping>odom:=odom</remapping>
                <remapping>distance:=distance</remapping>
                <remapping>effort:=effort</remapping>
                 <remapping>steering:=steering</remapping>
            </ros>
            <update_rate>60.0</update_rate>
            <front_left_joint>front_left_combined_joint</front_left_joint>
            <front_right_joint>front_right_combined_joint</front_right_joint>
            <rear_left_joint>rear_left_joint</rear_left_joint>
            <rear_right_joint>rear_right_joint</rear_right_joint>
            <left_steering_joint>front_left_combined_joint</left_steering_joint>
            <right_steering_joint>front_right_combined_joint</right_steering_joint>
            <steering_wheel_joint>steering_joint</steering_wheel_joint>
            <max_steer>0.6109</max_steer>
            <max_steering_angle>35.0</max_steering_angle>
            <max_speed>10</max_speed>
            <left_steering_pid_gain>1000 10 100</left_steering_pid_gain>
            <left_steering_i_range>0 1</left_steering_i_range>
            <right_steering_pid_gain>1000 10 100</right_steering_pid_gain>
            <right_steering_i_range>0 1</right_steering_i_range>
            <linear_velocity_pid_gain>100 0 1</linear_velocity_pid_gain>
            <linear_velocity_i_range>0 0</linear_velocity_i_range>
            <publish_odom>false</publish_odom>
            <publish_odom_tf>false</publish_odom_tf>
            <publish_wheel_tf>false</publish_wheel_tf>
            <publish_distance>true</publish_distance>
            <publish_effort>true</publish_effort>
            <publish_steering>true</publish_steering>
            <odometry_frame>odom</odometry_frame>
            <robot_base_frame>base_footprint</robot_base_frame>
        </plugin>
        <plugin name="botanbot_joint_states" filename="libgazebo_ros_joint_state_publisher.so">
            <ros>
                <argument>ros-args remap ~/out:=joint_states</argument>
            </ros>
            <update_rate>60</update_rate>
            <joint_name>front_left_combined_joint</joint_name>
            <joint_name>front_right_combined_joint</joint_name>
            <joint_name>rear_left_joint</joint_name>
            <joint_name>rear_right_joint</joint_name>
            <joint_name>rear_axle_joint</joint_name>
            <joint_name>steering_joint</joint_name>
        </plugin>
        <!-- END botanbot PLUGINS              -->
    </model>
</sdf>
